#VRML_SIM R2025a utf8

EXTERNPROTO "https://raw.githubusercontent.com/cyberbotics/webots/R2025a/projects/objects/backgrounds/protos/TexturedBackground.proto"
EXTERNPROTO "https://raw.githubusercontent.com/cyberbotics/webots/R2025a/projects/objects/backgrounds/protos/TexturedBackgroundLight.proto"
EXTERNPROTO "https://raw.githubusercontent.com/cyberbotics/webots/R2025a/projects/objects/floors/protos/RectangleArena.proto"

WorldInfo {
  contactProperties [
    ContactProperties {
      material2 "wheel"
      coulombFriction [
        0.02
      ]
    }
  ]
}
Viewpoint {
  orientation 0.5806025291230679 -0.5305493703284825 -0.6175905349177138 4.270879478736962
  position -3.0985162534943727 -2.643018182307748 3.0041596999564018
  follow "robot:solid(3)"
}
TexturedBackground {
}
TexturedBackgroundLight {
}
Solid {
  translation -0.59 0.31 -0.19
  children [
    Transform {
      scale 0.0009 0.0009 0.0009
      children [
        Shape {
          appearance PBRAppearance {
            baseColor 0 0.666667 1
            roughness 1
          }
          geometry Mesh {
            url [
              "DRC_blue_mid.stl"
            ]
          }
        }
        Shape {
          appearance PBRAppearance {
            baseColor 1 1 0.498039
            roughness 1
          }
          geometry Mesh {
            url [
              "DRC_yellow_mid.stl"
            ]
          }
        }
        Shape {
          appearance PBRAppearance {
            baseColor 0 0.666667 1
            roughness 1
          }
          geometry Mesh {
            url [
              "DRC_blue_main.stl"
            ]
          }
        }
        Shape {
          appearance PBRAppearance {
            baseColor 1 1 0.498039
            roughness 1
          }
          geometry Mesh {
            url [
              "DRC_yellow_main.stl"
            ]
          }
        }
      ]
    }
  ]
}
RectangleArena {
  floorSize 12 12
  floorAppearance PBRAppearance {
    baseColor 0.392157 0.392157 0.392157
    roughness 1
    metalness 0
  }
  wallHeight 1
}
Robot {
  translation -2.972261371335333 -2.3207889913610398 0.00954061980660656
  rotation 0.0031398362209989006 0.0018202826220449645 -0.9999934139781528 1.5297635070517437
  children [
    DEF Right HingeJoint {
      jointParameters HingeJointParameters {
        position -1.4211779205369772
        axis -0.5 0.866 0
        anchor -0.0668 0.116 0.02
      }
      device [
        RotationalMotor {
          name "Right_motor"
          maxVelocity 50
        }
      ]
      endPoint Solid {
        translation -0.06675952100909284 0.11575888550486303 0.01984109330336134
        rotation 0.3525452113308269 0.6103226810200028 -0.7093786710920046 3.9187596885301774
        children [
          DEF Right_wheel Shape {
            appearance PBRAppearance {
              baseColor 0 0 0
            }
            geometry Mesh {
              url [
                "Kiwi_wheel.stl"
              ]
            }
          }
        ]
        contactMaterial "wheel"
        boundingObject Pose {
          rotation 0.7071067811865475 0 0.7071067811865475 3.14159265
          children [
            Cylinder {
              height 0.0113
              radius 0.03015
            }
          ]
        }
        physics DEF Physics_wh Physics {
        }
      }
    }
    DEF Left HingeJoint {
      jointParameters HingeJointParameters {
        position 2.9565312668699333
        axis 0.5 0.866 0
        anchor -0.066815 -0.115727 0.02
      }
      device [
        RotationalMotor {
          name "Left_motor"
          maxVelocity 50
        }
      ]
      endPoint Solid {
        translation -0.0668269032273062 -0.11571999725285259 0.01999805615250364
        rotation -0.4983924604878556 0.8632381585318614 -0.08015508083323458 3.04933506466069
        children [
          DEF Left_wheel Shape {
            appearance PBRAppearance {
              baseColor 0 0 0
            }
            geometry Mesh {
              url [
                "Kiwi_wheel.stl"
              ]
            }
          }
        ]
        name "solid(1)"
        contactMaterial "wheel"
        boundingObject Pose {
          rotation 0.7071067811865475 0 0.7071067811865475 3.14159265
          children [
            Cylinder {
              height 0.0113
              radius 0.03015
            }
          ]
        }
        physics USE Physics_wh
      }
    }
    DEF Rear HingeJoint {
      jointParameters HingeJointParameters {
        position 7.2513930776940985
        anchor 0 0 0.02
      }
      device [
        RotationalMotor {
          name "Rear_motor"
          maxVelocity 50
        }
      ]
      endPoint Solid {
        translation 0.13363028409373667 -3.244515581629783e-08 0.02001290133116146
        rotation 0.9999999999983317 -1.617485241544726e-06 8.489114417220861e-07 0.968209459739731
        children [
          DEF Rear_wheel Shape {
            appearance PBRAppearance {
              baseColor 0 0 0
            }
            geometry Mesh {
              url [
                "Kiwi_wheel.stl"
              ]
            }
          }
        ]
        name "solid(2)"
        contactMaterial "wheel"
        boundingObject Pose {
          rotation 0.7071067811865475 0 0.7071067811865475 3.14159265
          children [
            Cylinder {
              height 0.0113
              radius 0.03015
            }
          ]
        }
        physics USE Physics_wh
      }
    }
    DEF Body Solid {
      children [
        Camera {
          translation -0.092 -0.014 0.202
          rotation -0.11772036362802256 0 0.9930467843899834 2.9769307941327137
          fieldOfView 0.96
          width 1280
          height 720
          far 100
        }
        DEF Body Shape {
          appearance PBRAppearance {
            baseColor 1 0 0
            roughness 1
          }
          geometry Mesh {
            url [
              "Kiwi_body.stl"
            ]
          }
        }
      ]
      name "solid(3)"
      boundingObject USE Body
      physics Physics {
        mass 1.7
        centerOfMass [
          0 0 -0.03
        ]
      }
    }
  ]
  contactMaterial "wheel"
  boundingObject Mesh {
    url [
      "Kiwi_body.stl"
    ]
  }
  physics Physics {
  }
  controller "Kiwi_Control"
}
