#VRML_SIM R2025a utf8

EXTERNPROTO "https://raw.githubusercontent.com/cyberbotics/webots/R2025a/projects/objects/backgrounds/protos/TexturedBackground.proto"
EXTERNPROTO "https://raw.githubusercontent.com/cyberbotics/webots/R2025a/projects/objects/backgrounds/protos/TexturedBackgroundLight.proto"
EXTERNPROTO "https://raw.githubusercontent.com/cyberbotics/webots/R2025a/projects/objects/floors/protos/RectangleArena.proto"

WorldInfo { title "DRC Track" basicTimeStep 16 coordinateSystem "ENU" }
Viewpoint { orientation 0 0 1 0 position 0 0 14 follow "kiwi_robot" followType "None" }
TexturedBackground { texture "empty_office" }
TexturedBackgroundLight { }
RectangleArena {
  floorSize 12 10
  floorAppearance PBRAppearance { baseColor 0.18 0.18 0.18 roughness 0.9 metalness 0 }
  wallHeight 0.05
}

  Solid {
    translation -4.2500 3.9820 0.0035
    children [ Shape { appearance PBRAppearance { baseColor 1.0 0.78 0.13 roughness 1 metalness 0 } geometry Box { size 0.5000 0.0360 0.0050 } } ]
    name "s0"
  }
  Solid {
    translation -3.7500 3.9820 0.0035
    children [ Shape { appearance PBRAppearance { baseColor 1.0 0.78 0.13 roughness 1 metalness 0 } geometry Box { size 0.5000 0.0360 0.0050 } } ]
    name "s1"
  }
  Solid {
    translation -3.2500 3.9820 0.0035
    children [ Shape { appearance PBRAppearance { baseColor 1.0 0.78 0.13 roughness 1 metalness 0 } geometry Box { size 0.5000 0.0360 0.0050 } } ]
    name "s2"
  }
  Solid {
    translation -2.2500 3.9820 0.0035
    children [ Shape { appearance PBRAppearance { baseColor 1.0 0.78 0.13 roughness 1 metalness 0 } geometry Box { size 0.5000 0.0360 0.0050 } } ]
    name "s3"
  }
  Solid {
    translation -0.7500 3.4820 0.0035
    children [ Shape { appearance PBRAppearance { baseColor 1.0 0.78 0.13 roughness 1 metalness 0 } geometry Box { size 0.5000 0.0360 0.0050 } } ]
    name "s4"
  }
  Solid {
    translation 0.7500 2.9820 0.0035
    children [ Shape { appearance PBRAppearance { baseColor 1.0 0.78 0.13 roughness 1 metalness 0 } geometry Box { size 0.5000 0.0360 0.0050 } } ]
    name "s5"
  }
  Solid {
    translation 2.2500 2.4820 0.0035
    children [ Shape { appearance PBRAppearance { baseColor 1.0 0.78 0.13 roughness 1 metalness 0 } geometry Box { size 0.5000 0.0360 0.0050 } } ]
    name "s6"
  }
  Solid {
    translation 2.7500 2.4820 0.0035
    children [ Shape { appearance PBRAppearance { baseColor 1.0 0.78 0.13 roughness 1 metalness 0 } geometry Box { size 0.5000 0.0360 0.0050 } } ]
    name "s7"
  }
  Solid {
    translation 3.2500 1.9820 0.0035
    children [ Shape { appearance PBRAppearance { baseColor 1.0 0.78 0.13 roughness 1 metalness 0 } geometry Box { size 0.5000 0.0360 0.0050 } } ]
    name "s8"
  }
  Solid {
    translation 3.7500 1.9820 0.0035
    children [ Shape { appearance PBRAppearance { baseColor 1.0 0.78 0.13 roughness 1 metalness 0 } geometry Box { size 0.5000 0.0360 0.0050 } } ]
    name "s9"
  }
  Solid {
    translation 4.2500 1.9820 0.0035
    children [ Shape { appearance PBRAppearance { baseColor 1.0 0.78 0.13 roughness 1 metalness 0 } geometry Box { size 0.5000 0.0360 0.0050 } } ]
    name "s10"
  }
  Solid {
    translation 4.2500 1.4820 0.0035
    children [ Shape { appearance PBRAppearance { baseColor 1.0 0.78 0.13 roughness 1 metalness 0 } geometry Box { size 0.5000 0.0360 0.0050 } } ]
    name "s11"
  }
  Solid {
    translation 3.7500 0.9820 0.0035
    children [ Shape { appearance PBRAppearance { baseColor 1.0 0.78 0.13 roughness 1 metalness 0 } geometry Box { size 0.5000 0.0360 0.0050 } } ]
    name "s12"
  }
  Solid {
    translation 3.2500 0.9820 0.0035
    children [ Shape { appearance PBRAppearance { baseColor 1.0 0.78 0.13 roughness 1 metalness 0 } geometry Box { size 0.5000 0.0360 0.0050 } } ]
    name "s13"
  }
  Solid {
    translation 2.7500 0.4820 0.0035
    children [ Shape { appearance PBRAppearance { baseColor 1.0 0.78 0.13 roughness 1 metalness 0 } geometry Box { size 0.5000 0.0360 0.0050 } } ]
    name "s14"
  }
  Solid {
    translation 2.2500 -0.0180 0.0035
    children [ Shape { appearance PBRAppearance { baseColor 1.0 0.78 0.13 roughness 1 metalness 0 } geometry Box { size 0.5000 0.0360 0.0050 } } ]
    name "s15"
  }
  Solid {
    translation 1.2500 -0.0180 0.0035
    children [ Shape { appearance PBRAppearance { baseColor 1.0 0.78 0.13 roughness 1 metalness 0 } geometry Box { size 0.5000 0.0360 0.0050 } } ]
    name "s16"
  }
  Solid {
    translation 0.7500 -0.5180 0.0035
    children [ Shape { appearance PBRAppearance { baseColor 1.0 0.78 0.13 roughness 1 metalness 0 } geometry Box { size 0.5000 0.0360 0.0050 } } ]
    name "s17"
  }
  Solid {
    translation -0.2500 -0.5180 0.0035
    children [ Shape { appearance PBRAppearance { baseColor 1.0 0.78 0.13 roughness 1 metalness 0 } geometry Box { size 0.5000 0.0360 0.0050 } } ]
    name "s18"
  }
  Solid {
    translation -0.7500 -0.5180 0.0035
    children [ Shape { appearance PBRAppearance { baseColor 1.0 0.78 0.13 roughness 1 metalness 0 } geometry Box { size 0.5000 0.0360 0.0050 } } ]
    name "s19"
  }
  Solid {
    translation -1.2500 -0.5180 0.0035
    children [ Shape { appearance PBRAppearance { baseColor 1.0 0.78 0.13 roughness 1 metalness 0 } geometry Box { size 0.5000 0.0360 0.0050 } } ]
    name "s20"
  }
  Solid {
    translation -1.7500 -0.5180 0.0035
    children [ Shape { appearance PBRAppearance { baseColor 1.0 0.78 0.13 roughness 1 metalness 0 } geometry Box { size 0.5000 0.0360 0.0050 } } ]
    name "s21"
  }
  Solid {
    translation -2.2500 -0.5180 0.0035
    children [ Shape { appearance PBRAppearance { baseColor 1.0 0.78 0.13 roughness 1 metalness 0 } geometry Box { size 0.5000 0.0360 0.0050 } } ]
    name "s22"
  }
  Solid {
    translation -2.7500 -0.5180 0.0035
    children [ Shape { appearance PBRAppearance { baseColor 1.0 0.78 0.13 roughness 1 metalness 0 } geometry Box { size 0.5000 0.0360 0.0050 } } ]
    name "s23"
  }
  Solid {
    translation -3.2500 -0.5180 0.0035
    children [ Shape { appearance PBRAppearance { baseColor 1.0 0.78 0.13 roughness 1 metalness 0 } geometry Box { size 0.5000 0.0360 0.0050 } } ]
    name "s24"
  }
  Solid {
    translation -3.2500 -0.0180 0.0035
    children [ Shape { appearance PBRAppearance { baseColor 1.0 0.78 0.13 roughness 1 metalness 0 } geometry Box { size 0.5000 0.0360 0.0050 } } ]
    name "s25"
  }
  Solid {
    translation -3.7500 -0.0180 0.0035
    children [ Shape { appearance PBRAppearance { baseColor 1.0 0.78 0.13 roughness 1 metalness 0 } geometry Box { size 0.5000 0.0360 0.0050 } } ]
    name "s26"
  }
  Solid {
    translation -3.7500 0.4820 0.0035
    children [ Shape { appearance PBRAppearance { baseColor 1.0 0.78 0.13 roughness 1 metalness 0 } geometry Box { size 0.5000 0.0360 0.0050 } } ]
    name "s27"
  }
  Solid {
    translation -3.7500 0.9820 0.0035
    children [ Shape { appearance PBRAppearance { baseColor 1.0 0.78 0.13 roughness 1 metalness 0 } geometry Box { size 0.5000 0.0360 0.0050 } } ]
    name "s28"
  }
  Solid {
    translation -3.2500 1.4820 0.0035
    children [ Shape { appearance PBRAppearance { baseColor 1.0 0.78 0.13 roughness 1 metalness 0 } geometry Box { size 0.5000 0.0360 0.0050 } } ]
    name "s29"
  }
  Solid {
    translation -3.2500 2.4820 0.0035
    children [ Shape { appearance PBRAppearance { baseColor 1.0 0.78 0.13 roughness 1 metalness 0 } geometry Box { size 0.5000 0.0360 0.0050 } } ]
    name "s30"
  }
  Solid {
    translation -2.7500 2.9820 0.0035
    children [ Shape { appearance PBRAppearance { baseColor 1.0 0.78 0.13 roughness 1 metalness 0 } geometry Box { size 0.5000 0.0360 0.0050 } } ]
    name "s31"
  }
  Solid {
    translation -2.2500 3.4820 0.0035
    children [ Shape { appearance PBRAppearance { baseColor 1.0 0.78 0.13 roughness 1 metalness 0 } geometry Box { size 0.5000 0.0360 0.0050 } } ]
    name "s32"
  }
  Solid {
    translation -1.7500 3.4820 0.0035
    children [ Shape { appearance PBRAppearance { baseColor 1.0 0.78 0.13 roughness 1 metalness 0 } geometry Box { size 0.5000 0.0360 0.0050 } } ]
    name "s33"
  }
  Solid {
    translation -1.2500 3.4820 0.0035
    children [ Shape { appearance PBRAppearance { baseColor 1.0 0.78 0.13 roughness 1 metalness 0 } geometry Box { size 0.5000 0.0360 0.0050 } } ]
    name "s34"
  }
  Solid {
    translation -0.7500 2.9820 0.0035
    children [ Shape { appearance PBRAppearance { baseColor 1.0 0.78 0.13 roughness 1 metalness 0 } geometry Box { size 0.5000 0.0360 0.0050 } } ]
    name "s35"
  }
  Solid {
    translation -0.2500 2.9820 0.0035
    children [ Shape { appearance PBRAppearance { baseColor 1.0 0.78 0.13 roughness 1 metalness 0 } geometry Box { size 0.5000 0.0360 0.0050 } } ]
    name "s36"
  }
  Solid {
    translation -0.2500 2.4820 0.0035
    children [ Shape { appearance PBRAppearance { baseColor 1.0 0.78 0.13 roughness 1 metalness 0 } geometry Box { size 0.5000 0.0360 0.0050 } } ]
    name "s37"
  }
  Solid {
    translation 0.2500 1.9820 0.0035
    children [ Shape { appearance PBRAppearance { baseColor 1.0 0.78 0.13 roughness 1 metalness 0 } geometry Box { size 0.5000 0.0360 0.0050 } } ]
    name "s38"
  }
  Solid {
    translation 0.2500 1.4820 0.0035
    children [ Shape { appearance PBRAppearance { baseColor 1.0 0.78 0.13 roughness 1 metalness 0 } geometry Box { size 0.5000 0.0360 0.0050 } } ]
    name "s39"
  }
  Solid {
    translation 0.2500 0.9820 0.0035
    children [ Shape { appearance PBRAppearance { baseColor 1.0 0.78 0.13 roughness 1 metalness 0 } geometry Box { size 0.5000 0.0360 0.0050 } } ]
    name "s40"
  }
  Solid {
    translation 0.2500 0.4820 0.0035
    children [ Shape { appearance PBRAppearance { baseColor 1.0 0.78 0.13 roughness 1 metalness 0 } geometry Box { size 0.5000 0.0360 0.0050 } } ]
    name "s41"
  }
  Solid {
    translation -0.2500 0.4820 0.0035
    children [ Shape { appearance PBRAppearance { baseColor 1.0 0.78 0.13 roughness 1 metalness 0 } geometry Box { size 0.5000 0.0360 0.0050 } } ]
    name "s42"
  }
  Solid {
    translation -0.2500 -0.0180 0.0035
    children [ Shape { appearance PBRAppearance { baseColor 1.0 0.78 0.13 roughness 1 metalness 0 } geometry Box { size 0.5000 0.0360 0.0050 } } ]
    name "s43"
  }
  Solid {
    translation -3.7500 -0.5180 0.0035
    children [ Shape { appearance PBRAppearance { baseColor 1.0 0.78 0.13 roughness 1 metalness 0 } geometry Box { size 0.5000 0.0360 0.0050 } } ]
    name "s44"
  }
  Solid {
    translation -4.2500 -0.5180 0.0035
    children [ Shape { appearance PBRAppearance { baseColor 1.0 0.78 0.13 roughness 1 metalness 0 } geometry Box { size 0.5000 0.0360 0.0050 } } ]
    name "s45"
  }
  Solid {
    translation -4.2500 -0.0180 0.0035
    children [ Shape { appearance PBRAppearance { baseColor 1.0 0.78 0.13 roughness 1 metalness 0 } geometry Box { size 0.5000 0.0360 0.0050 } } ]
    name "s46"
  }
  Solid {
    translation -4.2500 -1.0180 0.0035
    children [ Shape { appearance PBRAppearance { baseColor 1.0 0.78 0.13 roughness 1 metalness 0 } geometry Box { size 0.5000 0.0360 0.0050 } } ]
    name "s47"
  }
  Solid {
    translation -3.7500 -1.5180 0.0035
    children [ Shape { appearance PBRAppearance { baseColor 1.0 0.78 0.13 roughness 1 metalness 0 } geometry Box { size 0.5000 0.0360 0.0050 } } ]
    name "s48"
  }
  Solid {
    translation -3.2500 -2.0180 0.0035
    children [ Shape { appearance PBRAppearance { baseColor 1.0 0.78 0.13 roughness 1 metalness 0 } geometry Box { size 0.5000 0.0360 0.0050 } } ]
    name "s49"
  }
  Solid {
    translation -2.7500 -2.0180 0.0035
    children [ Shape { appearance PBRAppearance { baseColor 1.0 0.78 0.13 roughness 1 metalness 0 } geometry Box { size 0.5000 0.0360 0.0050 } } ]
    name "s50"
  }
  Solid {
    translation -2.2500 -2.0180 0.0035
    children [ Shape { appearance PBRAppearance { baseColor 1.0 0.78 0.13 roughness 1 metalness 0 } geometry Box { size 0.5000 0.0360 0.0050 } } ]
    name "s51"
  }
  Solid {
    translation -1.7500 -2.5180 0.0035
    children [ Shape { appearance PBRAppearance { baseColor 1.0 0.78 0.13 roughness 1 metalness 0 } geometry Box { size 0.5000 0.0360 0.0050 } } ]
    name "s52"
  }
  Solid {
    translation -1.2500 -2.5180 0.0035
    children [ Shape { appearance PBRAppearance { baseColor 1.0 0.78 0.13 roughness 1 metalness 0 } geometry Box { size 0.5000 0.0360 0.0050 } } ]
    name "s53"
  }
  Solid {
    translation -0.7500 -2.5180 0.0035
    children [ Shape { appearance PBRAppearance { baseColor 1.0 0.78 0.13 roughness 1 metalness 0 } geometry Box { size 0.5000 0.0360 0.0050 } } ]
    name "s54"
  }
  Solid {
    translation -0.2500 -2.5180 0.0035
    children [ Shape { appearance PBRAppearance { baseColor 1.0 0.78 0.13 roughness 1 metalness 0 } geometry Box { size 0.5000 0.0360 0.0050 } } ]
    name "s55"
  }
  Solid {
    translation 0.2500 -2.5180 0.0035
    children [ Shape { appearance PBRAppearance { baseColor 1.0 0.78 0.13 roughness 1 metalness 0 } geometry Box { size 0.5000 0.0360 0.0050 } } ]
    name "s56"
  }
  Solid {
    translation 0.7500 -2.0180 0.0035
    children [ Shape { appearance PBRAppearance { baseColor 1.0 0.78 0.13 roughness 1 metalness 0 } geometry Box { size 0.5000 0.0360 0.0050 } } ]
    name "s57"
  }
  Solid {
    translation 1.2500 -2.0180 0.0035
    children [ Shape { appearance PBRAppearance { baseColor 1.0 0.78 0.13 roughness 1 metalness 0 } geometry Box { size 0.5000 0.0360 0.0050 } } ]
    name "s58"
  }
  Solid {
    translation 1.7500 -2.0180 0.0035
    children [ Shape { appearance PBRAppearance { baseColor 1.0 0.78 0.13 roughness 1 metalness 0 } geometry Box { size 0.5000 0.0360 0.0050 } } ]
    name "s59"
  }
  Solid {
    translation 2.2500 -2.0180 0.0035
    children [ Shape { appearance PBRAppearance { baseColor 1.0 0.78 0.13 roughness 1 metalness 0 } geometry Box { size 0.5000 0.0360 0.0050 } } ]
    name "s60"
  }
  Solid {
    translation 2.7500 -2.0180 0.0035
    children [ Shape { appearance PBRAppearance { baseColor 1.0 0.78 0.13 roughness 1 metalness 0 } geometry Box { size 0.5000 0.0360 0.0050 } } ]
    name "s61"
  }
  Solid {
    translation 2.7500 -1.5180 0.0035
    children [ Shape { appearance PBRAppearance { baseColor 1.0 0.78 0.13 roughness 1 metalness 0 } geometry Box { size 0.5000 0.0360 0.0050 } } ]
    name "s62"
  }
  Solid {
    translation 3.2500 -1.5180 0.0035
    children [ Shape { appearance PBRAppearance { baseColor 1.0 0.78 0.13 roughness 1 metalness 0 } geometry Box { size 0.5000 0.0360 0.0050 } } ]
    name "s63"
  }
  Solid {
    translation 3.7500 -1.5180 0.0035
    children [ Shape { appearance PBRAppearance { baseColor 1.0 0.78 0.13 roughness 1 metalness 0 } geometry Box { size 0.5000 0.0360 0.0050 } } ]
    name "s64"
  }
  Solid {
    translation 4.2500 -1.5180 0.0035
    children [ Shape { appearance PBRAppearance { baseColor 1.0 0.78 0.13 roughness 1 metalness 0 } geometry Box { size 0.5000 0.0360 0.0050 } } ]
    name "s65"
  }
  Solid {
    translation 4.2500 -1.0180 0.0035
    children [ Shape { appearance PBRAppearance { baseColor 1.0 0.78 0.13 roughness 1 metalness 0 } geometry Box { size 0.5000 0.0360 0.0050 } } ]
    name "s66"
  }
  Solid {
    translation 4.7500 -1.0180 0.0035
    children [ Shape { appearance PBRAppearance { baseColor 1.0 0.78 0.13 roughness 1 metalness 0 } geometry Box { size 0.5000 0.0360 0.0050 } } ]
    name "s67"
  }
  Solid {
    translation 4.7500 -0.5180 0.0035
    children [ Shape { appearance PBRAppearance { baseColor 1.0 0.78 0.13 roughness 1 metalness 0 } geometry Box { size 0.5000 0.0360 0.0050 } } ]
    name "s68"
  }
  Solid {
    translation 4.2500 -0.0180 0.0035
    children [ Shape { appearance PBRAppearance { baseColor 1.0 0.78 0.13 roughness 1 metalness 0 } geometry Box { size 0.5000 0.0360 0.0050 } } ]
    name "s69"
  }
  Solid {
    translation 4.2500 0.4820 0.0035
    children [ Shape { appearance PBRAppearance { baseColor 1.0 0.78 0.13 roughness 1 metalness 0 } geometry Box { size 0.5000 0.0360 0.0050 } } ]
    name "s70"
  }
  Solid {
    translation 3.7500 0.4820 0.0035
    children [ Shape { appearance PBRAppearance { baseColor 1.0 0.78 0.13 roughness 1 metalness 0 } geometry Box { size 0.5000 0.0360 0.0050 } } ]
    name "s71"
  }
  Solid {
    translation 3.2500 0.4820 0.0035
    children [ Shape { appearance PBRAppearance { baseColor 1.0 0.78 0.13 roughness 1 metalness 0 } geometry Box { size 0.5000 0.0360 0.0050 } } ]
    name "s72"
  }
  Solid {
    translation 2.2500 0.4820 0.0035
    children [ Shape { appearance PBRAppearance { baseColor 1.0 0.78 0.13 roughness 1 metalness 0 } geometry Box { size 0.5000 0.0360 0.0050 } } ]
    name "s73"
  }
  Solid {
    translation 1.7500 0.4820 0.0035
    children [ Shape { appearance PBRAppearance { baseColor 1.0 0.78 0.13 roughness 1 metalness 0 } geometry Box { size 0.5000 0.0360 0.0050 } } ]
    name "s74"
  }
  Solid {
    translation 0.7500 0.4820 0.0035
    children [ Shape { appearance PBRAppearance { baseColor 1.0 0.78 0.13 roughness 1 metalness 0 } geometry Box { size 0.5000 0.0360 0.0050 } } ]
    name "s75"
  }
  Solid {
    translation -0.7500 -0.0180 0.0035
    children [ Shape { appearance PBRAppearance { baseColor 1.0 0.78 0.13 roughness 1 metalness 0 } geometry Box { size 0.5000 0.0360 0.0050 } } ]
    name "s76"
  }
  Solid {
    translation -1.2500 -0.0180 0.0035
    children [ Shape { appearance PBRAppearance { baseColor 1.0 0.78 0.13 roughness 1 metalness 0 } geometry Box { size 0.5000 0.0360 0.0050 } } ]
    name "s77"
  }

Robot {
  name "kiwi_robot"
  translation -4.250 3.750 0.0694759
  rotation 0 0 1 0
  children [

    GPS { name "gps" }
    Gyro { name "gyro" }

    DEF BODY_SHAPE Pose {
      translation 0 0 0.03
      children [
        Shape {
          appearance PBRAppearance { baseColor 0.1 0.5 0.9 roughness 0.4 metalness 0.2 }
          geometry Cylinder { height 0.12 radius 0.10 subdivision 18 }
        }
      ]
    }

    DEF NOSE Pose {
      translation 0.10 0 0.06
      children [
        Shape {
          appearance PBRAppearance { baseColor 1 0.3 0.1 }
          geometry Sphere { radius 0.015 }
        }
      ]
    }

    DEF SOLID1 Solid {
      children [
        HingeJoint {
          jointParameters HingeJointParameters { anchor -0.1 0 0 }
          device [ RotationalMotor { name "wheel0" maxVelocity 40 maxTorque 10 } PositionSensor { name "wheel0_sensor" } ]
          endPoint Solid {
            translation -0.138 0 0
            children [
              DEF sr1_0 HingeJoint { jointParameters HingeJointParameters { axis 0 1 0 anchor -0.02 0 0.035 } endPoint Solid { translation -0.02 0 0.035 children [ DEF r1 Pose { rotation 1 0 0 1.5708 children [ DEF ROLLER Shape { appearance PBRAppearance { baseColor 0.2 0.2 0.2 roughness 1 metalness 0 } geometry Cylinder { height 0.014 radius 0.008 } } ] } ] name "w0r1" boundingObject USE r1 physics Physics { density -1 mass 0.05 } } }
              DEF sr2_0 HingeJoint { jointParameters HingeJointParameters { axis 0 -0.707107 0.707107 anchor -0.02 0.02475 0.02475 } endPoint Solid { translation -0.02 0.02475 0.02475 children [ DEF r2 Pose { rotation 1 0 0 2.27 children [ USE ROLLER ] } ] name "w0r2" boundingObject USE r2 physics Physics { density -1 mass 0.05 } } }
              DEF sr3_0 HingeJoint { jointParameters HingeJointParameters { axis 0 0 1 anchor -0.02 0.035 0 } endPoint Solid { translation -0.02 0.035 0 children [ DEF r3 Pose { children [ USE ROLLER ] } ] name "w0r3" boundingObject USE r3 physics Physics { density -1 mass 0.05 } } }
              DEF sr4_0 HingeJoint { jointParameters HingeJointParameters { axis 0 0.707107 0.707107 anchor -0.02 0.02475 -0.02475 } endPoint Solid { translation -0.02 0.02475 -0.02475 children [ DEF r4 Pose { rotation 1 0 0 0.76 children [ USE ROLLER ] } ] name "w0r4" boundingObject USE r4 physics Physics { density -1 mass 0.05 } } }
              DEF sr5_0 HingeJoint { jointParameters HingeJointParameters { axis 0 1 0 anchor -0.02 0 -0.035 } endPoint Solid { translation -0.02 0 -0.035 children [ DEF r5 Pose { rotation 1 0 0 1.5708 children [ USE ROLLER ] } ] name "w0r5" boundingObject USE r5 physics Physics { density -1 mass 0.05 } } }
              DEF sr6_0 HingeJoint { jointParameters HingeJointParameters { axis 0 -0.707107 0.707107 anchor -0.02 -0.02475 -0.02475 } endPoint Solid { translation -0.02 -0.02475 -0.02475 children [ DEF r6 Pose { rotation 1 0 0 2.27 children [ USE ROLLER ] } ] name "w0r6" boundingObject USE r6 physics Physics { density -1 mass 0.05 } } }
              DEF sr7_0 HingeJoint { jointParameters HingeJointParameters { axis 0 0 1 anchor -0.02 -0.035 0 } endPoint Solid { translation -0.02 -0.035 0 children [ DEF r7 Pose { children [ USE ROLLER ] } ] name "w0r7" boundingObject USE r7 physics Physics { density -1 mass 0.05 } } }
              DEF sr8_0 HingeJoint { jointParameters HingeJointParameters { axis 0 0.707107 0.707107 anchor -0.02 -0.02475 0.02475 } endPoint Solid { translation -0.02 -0.02475 0.02475 children [ DEF r8 Pose { rotation 1 0 0 0.76 children [ USE ROLLER ] } ] name "w0r8" boundingObject USE r8 physics Physics { density -1 mass 0.05 } } }
              DEF WHEEL_VIS Pose { translation -0.02 0 0 rotation 0 1 0 1.5708 children [ Shape { appearance PBRAppearance { baseColor 0.15 0.15 0.15 roughness 1 metalness 0 } geometry Cylinder { height 0.018 radius 0.035 subdivision 20 } } ] }
            ]
            boundingObject Pose { translation -0.02 0 0 rotation 0 1 0 1.5708 children [ Shape { geometry Cylinder { height 0.018 radius 0.035 } } ] }
            physics Physics { }
          }
        }
      ]
      name "wheel0_body"
      boundingObject DEF DUMMY Sphere { radius 0.001 }
      physics Physics { }
    }

    DEF SOLID2 Solid {
      rotation 0 0 1 2.0944
      children [
        HingeJoint {
          jointParameters HingeJointParameters { anchor -0.1 0 0 }
          device [ RotationalMotor { name "wheel1" maxVelocity 40 maxTorque 10 } PositionSensor { name "wheel1_sensor" } ]
          endPoint Solid {
            translation -0.138 0 0
            children [
              DEF sr1_1 HingeJoint { jointParameters HingeJointParameters { axis 0 1 0 anchor -0.02 0 0.035 } endPoint Solid { translation -0.02 0 0.035 children [ USE r1 ] name "w1r1" boundingObject USE r1 physics Physics { density -1 mass 0.05 } } }
              DEF sr2_1 HingeJoint { jointParameters HingeJointParameters { axis 0 -0.707107 0.707107 anchor -0.02 0.02475 0.02475 } endPoint Solid { translation -0.02 0.02475 0.02475 children [ USE r2 ] name "w1r2" boundingObject USE r2 physics Physics { density -1 mass 0.05 } } }
              DEF sr3_1 HingeJoint { jointParameters HingeJointParameters { axis 0 0 1 anchor -0.02 0.035 0 } endPoint Solid { translation -0.02 0.035 0 children [ USE r3 ] name "w1r3" boundingObject USE r3 physics Physics { density -1 mass 0.05 } } }
              DEF sr4_1 HingeJoint { jointParameters HingeJointParameters { axis 0 0.707107 0.707107 anchor -0.02 0.02475 -0.02475 } endPoint Solid { translation -0.02 0.02475 -0.02475 children [ USE r4 ] name "w1r4" boundingObject USE r4 physics Physics { density -1 mass 0.05 } } }
              DEF sr5_1 HingeJoint { jointParameters HingeJointParameters { axis 0 1 0 anchor -0.02 0 -0.035 } endPoint Solid { translation -0.02 0 -0.035 children [ USE r5 ] name "w1r5" boundingObject USE r5 physics Physics { density -1 mass 0.05 } } }
              DEF sr6_1 HingeJoint { jointParameters HingeJointParameters { axis 0 -0.707107 0.707107 anchor -0.02 -0.02475 -0.02475 } endPoint Solid { translation -0.02 -0.02475 -0.02475 children [ USE r6 ] name "w1r6" boundingObject USE r6 physics Physics { density -1 mass 0.05 } } }
              DEF sr7_1 HingeJoint { jointParameters HingeJointParameters { axis 0 0 1 anchor -0.02 -0.035 0 } endPoint Solid { translation -0.02 -0.035 0 children [ USE r7 ] name "w1r7" boundingObject USE r7 physics Physics { density -1 mass 0.05 } } }
              DEF sr8_1 HingeJoint { jointParameters HingeJointParameters { axis 0 0.707107 0.707107 anchor -0.02 -0.02475 0.02475 } endPoint Solid { translation -0.02 -0.02475 0.02475 children [ USE r8 ] name "w1r8" boundingObject USE r8 physics Physics { density -1 mass 0.05 } } }
              USE WHEEL_VIS
            ]
            boundingObject Pose { translation -0.02 0 0 rotation 0 1 0 1.5708 children [ Shape { geometry Cylinder { height 0.018 radius 0.035 } } ] }
            physics Physics { }
          }
        }
      ]
      name "wheel1_body"
      boundingObject USE DUMMY
      physics Physics { }
    }

    DEF SOLID3 Solid {
      rotation 0 0 1 4.1888
      children [
        HingeJoint {
          jointParameters HingeJointParameters { anchor -0.1 0 0 }
          device [ RotationalMotor { name "wheel2" maxVelocity 40 maxTorque 10 } PositionSensor { name "wheel2_sensor" } ]
          endPoint Solid {
            translation -0.138 0 0
            children [
              DEF sr1_2 HingeJoint { jointParameters HingeJointParameters { axis 0 1 0 anchor -0.02 0 0.035 } endPoint Solid { translation -0.02 0 0.035 children [ USE r1 ] name "w2r1" boundingObject USE r1 physics Physics { density -1 mass 0.05 } } }
              DEF sr2_2 HingeJoint { jointParameters HingeJointParameters { axis 0 -0.707107 0.707107 anchor -0.02 0.02475 0.02475 } endPoint Solid { translation -0.02 0.02475 0.02475 children [ USE r2 ] name "w2r2" boundingObject USE r2 physics Physics { density -1 mass 0.05 } } }
              DEF sr3_2 HingeJoint { jointParameters HingeJointParameters { axis 0 0 1 anchor -0.02 0.035 0 } endPoint Solid { translation -0.02 0.035 0 children [ USE r3 ] name "w2r3" boundingObject USE r3 physics Physics { density -1 mass 0.05 } } }
              DEF sr4_2 HingeJoint { jointParameters HingeJointParameters { axis 0 0.707107 0.707107 anchor -0.02 0.02475 -0.02475 } endPoint Solid { translation -0.02 0.02475 -0.02475 children [ USE r4 ] name "w2r4" boundingObject USE r4 physics Physics { density -1 mass 0.05 } } }
              DEF sr5_2 HingeJoint { jointParameters HingeJointParameters { axis 0 1 0 anchor -0.02 0 -0.035 } endPoint Solid { translation -0.02 0 -0.035 children [ USE r5 ] name "w2r5" boundingObject USE r5 physics Physics { density -1 mass 0.05 } } }
              DEF sr6_2 HingeJoint { jointParameters HingeJointParameters { axis 0 -0.707107 0.707107 anchor -0.02 -0.02475 -0.02475 } endPoint Solid { translation -0.02 -0.02475 -0.02475 children [ USE r6 ] name "w2r6" boundingObject USE r6 physics Physics { density -1 mass 0.05 } } }
              DEF sr7_2 HingeJoint { jointParameters HingeJointParameters { axis 0 0 1 anchor -0.02 -0.035 0 } endPoint Solid { translation -0.02 -0.035 0 children [ USE r7 ] name "w2r7" boundingObject USE r7 physics Physics { density -1 mass 0.05 } } }
              DEF sr8_2 HingeJoint { jointParameters HingeJointParameters { axis 0 0.707107 0.707107 anchor -0.02 -0.02475 0.02475 } endPoint Solid { translation -0.02 -0.02475 0.02475 children [ USE r8 ] name "w2r8" boundingObject USE r8 physics Physics { density -1 mass 0.05 } } }
              USE WHEEL_VIS
            ]
            boundingObject Pose { translation -0.02 0 0 rotation 0 1 0 1.5708 children [ Shape { geometry Cylinder { height 0.018 radius 0.035 } } ] }
            physics Physics { }
          }
        }
      ]
      name "wheel2_body"
      boundingObject USE DUMMY
      physics Physics { }
    }

  ]
  boundingObject USE BODY_SHAPE
  physics Physics { density -1 mass 1.2 centerOfMass [ 0 0 0 ] }
  supervisor TRUE
  controller "kiwi_controller"
}
